Workbook
Name Praznici: Podaci!$P$3:$P$16
Name Praznici: Podaci!$P$3:$Q$16
Name Praznici2024: Podaci!$P$3:$Q$16

Sheet Podaci
A1: www.metro-servis.hr
A2: Ovdje upišite opće podatke o tvrtki da se mogu raspodijeliti po obrascima .
A3: PODACI O TVRTKI | P3: 46023 | Q3: Nova godina
A4: IME I PREZIME obrtnika / NAZIV TVRTKE | B4: TVRTKA ABC D.O.O. | D4: MOLIMO OVJDE UPISATI PODATKE OD TVRTKE - POSLODAVCA | P4: 46028 | Q4: Sveta tri kralja
A5: OIB | B5: 12345678910 | D5: OVI PODACI SE AUTOMATSKI PRENOSE NA POJEDINAČNE MJESEČNE LISTE | P5: 46117 | Q5: Uskrs
A6: MB OBRTA / MB | B6: 12345678 | D6: MOŽETE IH I COPY + PASTE IZ OBRASCA ERA PRETHODNE GODINE | P6: 46118 | Q6: Uskrsni ponedjeljak
A7: MATIČNI BROJ OBRTA / MBS | B7: 321321321321321 | P7: 46143 | Q7: Praznik rada
A8: ŠIFRA DJELATNOSTI | B8: 1425 | P8: 46172 | Q8: Tijelovo
A9: NAZIV DJELATNOSTI | B9: NEŠTO | P9: 46177 | Q9: Dan državnosti
A10: IBAN | B10: HR1210010051863000160 | P10: 46195 | Q10: Dan antifašističke borbe
P11: 46239 | Q11: Dan pobjede i domovinske zahvalnosti i Dan hrvatskih branitelja
A12: ADRESA | B12: ADRESA 1 | P12: 46249 | Q12: Velika gospa
A13: GRAD, ULICA I BROJ | B13: GRAD, ADRESA 1 | P13: 46327 | Q13: Dan svih svetih
A14: NASELJE | B14: NASELJE | P14: 46344 | Q14: Dan sjećanja na žrtve Domovinskog rata i Dan sjećanja na žrtvu Vukovara i Škabrnje
P15: 46381 | Q15: Božić
P16: 46382 | Q16: Drugi dan Božića (Sv. Stjepan)
A17: PODACI O RADNIKU | D17: MOLIMO OVDJE UPISATI PODATKE O RADNIKU
A18: IME I PREZIME | B18: MARICA MARINČIĆ | D18: OVI PODACI SE AUTOMATSKI PRENOSE NA POJEDINAČNE MJESEČNE LISTE
A19: OIB | B19: 78945612389 | C19: =+TODAY() -> 46028 | D19: MOŽETE IH I COPY + PASTE IZ OBRASCA ERA PRETHODNE GODINE
A20: DATUM ROĐENJA | B20: 35916
A21: ADRESA | B21: ADRESA 1
A22: GRAD, ULICA I BROJ | B22: KARLOVAC
A23: NASELJE
A24: DATUM POČETKA RADA | B24: 45275
A25: DATUM ZAVRŠETKA RADA
A26: SATI RADA | B26: 8
A27: Satnica - Pon-Pet po 8 sati ? | B27: DA
A28: Satnica - Pon-Sub - 7 + 5 ? | B28: =+IF(+B27="NE","DA","NE") -> NE
A29: Obračunavati minuli rad ? DA / NE | B29: DA
A30: Godišnji iz prethodne godine za prenijeti | B30: 5
A31: email zaposlenika | B31: info@metro-servis.hr
A33: Datum | B33: Državni praznik | C33: Dan
A34: 46023 | B34: Nova godina | C34: =+TEXT(A34,"ddd") -> čet
A35: 46028 | B35: Bogojavljenje ili Sveta tri kralja | C35: =+TEXT(A35,"ddd") -> uto
A36: 46117 | B36: Uskrs | C36: =+TEXT(A36,"ddd") -> ned
A37: 46118 | B37: Uskrsni ponedjeljak | C37: =+TEXT(A37,"ddd") -> pon
A38: 46143 | B38: Praznik rada | C38: =+TEXT(A38,"ddd") -> pet
A39: 46172 | B39: Dan državnosti | C39: =+TEXT(A39,"ddd") -> sub
A40: 46177 | B40: Tijelovo | C40: =+TEXT(A40,"ddd") -> čet
A41: 46195 | B41: Dan antifašističke borbe | C41: =+TEXT(A41,"ddd") -> pon
...

Sheet 01
A1: EVIDENCIJA O RADNOM VREMENU ZAPOSLENIKA
A2: RAD U SMJENAMA ? | E2: NE
A3: Raspored 1.smjena | E3: 6 | F3: 14 | G3: Ime i prezime radnika: | M3: =+Podaci!B18 -> MARICA MARINČIĆ | S3: NAZIV TVRTKE I OIB:
A4: Raspored 2.smjena | E4: 14 | F4: 22 | G4: OIB radnika: | M4: =+Podaci!B19 -> 78945612389 | S4: =+Podaci!B4 -> TVRTKA ABC D.O.O.
A5: Noćni rad | E5: 22 | F5: 6 | G5: E-MAIL radnika: | M5: =+Podaci!B31 -> info@metro-servis.hr | S5: =+Podaci!B5 -> 12345678910
A6: MJESEC | D6: =+MONTH(D7) -> 1 | G6: GODINA | J6: =+YEAR(J7) -> 2026 | R6: Broj radnih sati | V6: 7 + 5 | X6: Mogući broj sati u mjesecu
A7: Datum početka | D7: =+A12 -> 46023 | G7: Datum kraja | J7: =+EOMONTH(D7,0) -> 46053 | M7: Broj radnih dana | P7: =+NETWORKDAYS(D7,J7,0) -> 22 | R7: Broj radnih sati | V7: 8 | X7: Mogući broj sati u mjesecu | AC7: =+P7*V7 -> 176
A9: =+YEAR(A12) -> 2026 | F9: Vrijeme / Sati nazočnosti na poslu | N9: Vrijeme / Sati nenazočnosti na poslu zbog
A10: Datum | B10: Dan | C10: Početak rada | D10: Završetak rada | E10: Ukupno sati | F10: 1.smjena | G10: 2.smjena | H10: Noćni rad | I10: Rad Nedjeljom | J10: Rad praznikom | K10: Prekovremeni rad | L10: Vrijeme terenskog rada | M10: Vrijeme pripravnosti | N10: Dnevni odmor | O10: Tjedni odmor | P10: Godišnji odmor | Q10: Neradni dani - blagdani | R10: Privremena nesposobnost za rad - do 42 dana | S10: Privremena nesposobnost za rad - iznad 42 dana | T10: Porodiljni - rodiljni dopust | U10: Plaćeni dopust - odsustnost s rada | V10: Sati očinskog dopusta i dopusta drugog posvojitelja | W10: Neplaćeni dopust - pruž.osobne skrbi | X10: Neplaćen dopust kandidata - razno | Y10: Neplaćeni dopust - na zahtjev radnika | Z10: Krivnje radnika - ne obavlja ugovorene poslove | AA10: Krivnja poslodavca - zastoj | AB10: Vojna obveza ili služenje u ugovornoj pričuvi | AC10: štrajka | AD10: isključenja s rada - lockout | AE10: KONTROLNI ZBROJ
A12: 46023 | B12: =+TEXT(A12,"DDD") -> čet | E12: =+D12-C12 -> 0 | AE12: =SUM(F12:AD12) -> 0
A13: =+A12+1 -> 46024 | B13: =+TEXT(A13,"DDD") -> pet | E13: =+D13-C13 -> 0 | AE13: =SUM(F13:AD13) -> 0
A14: =+A13+1 -> 46025 | B14: =+TEXT(A14,"DDD") -> sub | E14: =+D14-C14 -> 0 | AE14: =SUM(F14:AD14) -> 0
A15: =+A14+1 -> 46026 | B15: =+TEXT(A15,"DDD") -> ned | E15: =+D15-C15 -> 0 | AE15: =SUM(F15:AD15) -> 0
A16: =+A15+1 -> 46027 | B16: =+TEXT(A16,"DDD") -> pon | E16: =+D16-C16 -> 0 | AE16: =SUM(F16:AD16) -> 0
A17: =+A16+1 -> 46028 | B17: =+TEXT(A17,"DDD") -> uto | E17: =+D17-C17 -> 0 | AE17: =SUM(F17:AD17) -> 0
A18: =+A17+1 -> 46029 | B18: =+TEXT(A18,"DDD") -> sri | E18: =+D18-C18 -> 0 | AE18: =SUM(F18:AD18) -> 0
A19: =+A18+1 -> 46030 | B19: =+TEXT(A19,"DDD") -> čet | E19: =+D19-C19 -> 0 | AE19: =SUM(F19:AD19) -> 0
A20: =+A19+1 -> 46031 | B20: =+TEXT(A20,"DDD") -> pet | E20: =+D20-C20 -> 0 | AE20: =SUM(F20:AD20) -> 0
A21: =+A20+1 -> 46032 | B21: =+TEXT(A21,"DDD") -> sub | E21: =+D21-C21 -> 0 | AE21: =SUM(F21:AD21) -> 0
A22: =+A21+1 -> 46033 | B22: =+TEXT(A22,"DDD") -> ned | E22: =+D22-C22 -> 0 | AE22: =SUM(F22:AD22) -> 0
A23: =+A22+1 -> 46034 | B23: =+TEXT(A23,"DDD") -> pon | E23: =+D23-C23 -> 0 | AE23: =SUM(F23:AD23) -> 0
A24: =+A23+1 -> 46035 | B24: =+TEXT(A24,"DDD") -> uto | E24: =+D24-C24 -> 0 | AE24: =SUM(F24:AD24) -> 0
... A42: =+A41+1 -> 46053 | B42: =+TEXT(A42,"DDD") -> sub | E42: =+D42-C42 -> 0 | AE42: =SUM(F42:AD42) -> 0
A44: *** | B44: *** | C44: *** | D44: *** | E44: =SUM(E12:E43) -> 0 | F44: =SUM(F12:F43) -> 0 | G44: =SUM(G12:G43) -> 0 | H44: =SUM(H12:H43) -> 0 | I44: =SUM(I12:I43) -> 0 | J44: =SUM(J12:J43) -> 0 | K44: =SUM(K12:K43) -> 0 | L44: =SUM(L12:L43) -> 0 | ... AD44: =SUM(AD12:AD43) -> 0 | AE44: ***
E45: =+E10 -> Ukupno sati | F45: =+F10 -> 1.smjena | G45: =+G10 -> 2.smjena | H45: =+H10 -> Noćni rad | I45: =+I10 -> Rad Nedjeljom | J45: =+J10 -> Rad praznikom | K45: =+K10 -> Prekovremeni rad | L45: =+L10 -> Vrijeme terenskog rada | ... AE45: =+AE10 -> KONTROLNI ZBROJ
A46: Broj sati nazočnosti na poslu: | G46: =+SUM(F44:M44) -> 0 | J46: Ukupan broj sati : | P46: =+G46+G47 -> 0 | S46: Postotak minulog rada:
A47: Broj sati NEnazočnosti na poslu: | G47: =+SUM(P44:AD44) -> 0

Sheet 02
A1: EVIDENCIJA O RADNOM VREMENU ZAPOSLENIKA
A2: RAD U SMJENAMA ? | E2: =+'01'!E2 -> NE
A3: Raspored 1.smjena | E3: 6 | F3: 14 | G3: Ime i prezime radnika: | M3: =+Podaci!B18 -> MARICA MARINČIĆ | S3: NAZIV TVRTKE I OIB:
A4: Raspored 2.smjena | E4: 14 | F4: 22 | G4: OIB radnika: | M4: =+Podaci!B19 -> 78945612389 | S4: =+Podaci!B4 -> TVRTKA ABC D.O.O.
A5: Noćni rad | E5: 22 | F5: 6 | G5: E-MAIL radnika: | M5: =+Podaci!B31 -> info@metro-servis.hr | S5: =+Podaci!B5 -> 12345678910
A6: MJESEC | D6: =+MONTH(D7) -> 2 | G6: GODINA | J6: =+YEAR(J7) -> 2026 | R6: Broj radnih sati | V6: 7 + 5 | X6: Mogući broj sati u mjesecu
A7: Datum početka | D7: =+A12 -> 46054 | G7: Datum kraja | J7: =+EOMONTH(D7,0) -> 46081 | M7: Broj radnih dana | P7: =+NETWORKDAYS(D7,J7,0) -> 20 | R7: Broj radnih sati | V7: 8 | X7: Mogući broj sati u mjesecu | AC7: =+P7*V7 -> 160
A9: =+YEAR(A12) -> 2026 | F9: Vrijeme / Sati nazočnosti na poslu | N9: Vrijeme / Sati nenazočnosti na poslu zbog
A10: Datum | B10: Dan | C10: Početak rada | D10: Završetak rada | E10: Ukupno sati | F10: 1.smjena | G10: 2.smjena | H10: Noćni rad | I10: Rad Nedjeljom | J10: Rad praznikom | K10: Prekovremeni rad | L10: Vrijeme terenskog rada | M10: Vrijeme pripravnosti | N10: Dnevni odmor | O10: Tjedni odmor | P10: Godišnji odmor | Q10: Neradni dani - blagdani | R10: Privremena nesposobnost za rad - do 42 dana | S10: Privremena nesposobnost za rad - iznad 42 dana | T10: Porodiljni - rodiljni dopust | U10: Plaćeni dopust - odsustnost s rada | V10: Sati očinskog dopusta i dopusta drugog posvojitelja | W10: Neplaćeni dopust - pruž.osobne skrbi | X10: Neplaćen dopust kandidata - razno | Y10: Neplaćeni dopust - na zahtjev radnika | Z10: Krivnje radnika - ne obavlja ugovorene poslove | AA10: Krivnja poslodavca - zastoj | AB10: Vojna obveza ili služenje u ugovornoj pričuvi | AC10: štrajka | AD10: isključenja s rada - lockout | AE10: KONTROLNI ZBROJ
A12: 46054 | B12: =+TEXT(A12,"DDD") -> ned | E12: =+D12-C12 -> 0 | AE12: =SUM(F12:AD12) -> 0
A13: =+A12+1 -> 46055 | B13: =+TEXT(A13,"DDD") -> pon | E13: =+D13-C13 -> 0 | AE13: =SUM(F13:AD13) -> 0
A14: =+A13+1 -> 46056 | B14: =+TEXT(A14,"DDD") -> uto | E14: =+D14-C14 -> 0 | AE14: =SUM(F14:AD14) -> 0
A15: =+A14+1 -> 46057 | B15: =+TEXT(A15,"DDD") -> sri | E15: =+D15-C15 -> 0 | AE15: =SUM(F15:AD15) -> 0
A16: =+A15+1 -> 46058 | B16: =+TEXT(A16,"DDD") -> čet | E16: =+D16-C16 -> 0 | AE16: =SUM(F16:AD16) -> 0
A17: =+A16+1 -> 46059 | B17: =+TEXT(A17,"DDD") -> pet | E17: =+D17-C17 -> 0 | AE17: =SUM(F17:AD17) -> 0
A18: =+A17+1 -> 46060 | B18: =+TEXT(A18,"DDD") -> sub | E18: =+D18-C18 -> 0 | AE18: =SUM(F18:AD18) -> 0
A19: =+A18+1 -> 46061 | B19: =+TEXT(A19,"DDD") -> ned | E19: =+D19-C19 -> 0 | AE19: =SUM(F19:AD19) -> 0
A20: =+A19+1 -> 46062 | B20: =+TEXT(A20,"DDD") -> pon | E20: =+D20-C20 -> 0 | AE20: =SUM(F20:AD20) -> 0
A21: =+A20+1 -> 46063 | B21: =+TEXT(A21,"DDD") -> uto | E21: =+D21-C21 -> 0 | AE21: =SUM(F21:AD21) -> 0
A22: =+A21+1 -> 46064 | B22: =+TEXT(A22,"DDD") -> sri | E22: =+D22-C22 -> 0 | AE22: =SUM(F22:AD22) -> 0
A23: =+A22+1 -> 46065 | B23: =+TEXT(A23,"DDD") -> čet | E23: =+D23-C23 -> 0 | AE23: =SUM(F23:AD23) -> 0
A24: =+A23+1 -> 46066 | B24: =+TEXT(A24,"DDD") -> pet | E24: =+D24-C24 -> 0 | AE24: =SUM(F24:AD24) -> 0
... A39: =+A38+1 -> 46081 | B39: =+TEXT(A39,"DDD") -> sub | E39: =+D39-C39 -> 0 | AE39: =SUM(F39:AD39) -> 0
A44: *** | B44: *** | C44: *** | D44: *** | E44: =SUM(E12:E43) -> 0 | F44: =SUM(F12:F43) -> 0 | G44: =SUM(G12:G43) -> 0 | H44: =SUM(H12:H43) -> 0 | I44: =SUM(I12:I43) -> 0 | J44: =SUM(J12:J43) -> 0 | K44: =SUM(K12:K43) -> 0 | L44: =SUM(L12:L43) -> 0 | ... AD44: =SUM(AD12:AD43) -> 0 | AE44: ***
E45: =+E10 -> Ukupno sati | F45: =+F10 -> 1.smjena | G45: =+G10 -> 2.smjena | H45: =+H10 -> Noćni rad | I45: =+I10 -> Rad Nedjeljom | J45: =+J10 -> Rad praznikom | K45: =+K10 -> Prekovremeni rad | L45: =+L10 -> Vrijeme terenskog rada | ... AE45: =+AE10 -> KONTROLNI ZBROJ
A46: Broj sati nazočnosti na poslu: | G46: =+SUM(F44:M44) -> 0 | J46: Ukupan broj sati : | P46: =+G46+G47 -> 0 | S46: Postotak minulog rada:
A47: Broj sati NEnazočnosti na poslu: | G47: =+SUM(P44:AD44) -> 0

Sheet 03
A1: EVIDENCIJA O RADNOM VREMENU ZAPOSLENIKA
A2: RAD U SMJENAMA ? | E2: =+'01'!E2 -> NE
A3: Raspored 1.smjena | E3: 6 | F3: 14 | G3: Ime i prezime radnika: | M3: =+Podaci!B18 -> MARICA MARINČIĆ | S3: NAZIV TVRTKE I OIB:
A4: Raspored 2.smjena | E4: 14 | F4: 22 | G4: OIB radnika: | M4: =+Podaci!B19 -> 78945612389 | S4: =+Podaci!B4 -> TVRTKA ABC D.O.O.
A5: Noćni rad | E5: 22 | F5: 6 | G5: E-MAIL radnika: | M5: =+Podaci!B31 -> info@metro-servis.hr | S5: =+Podaci!B5 -> 12345678910
A6: MJESEC | D6: =+MONTH(D7) -> 3 | G6: GODINA | J6: =+YEAR(J7) -> 2026 | R6: Broj radnih sati | V6: 7 + 5 | X6: Mogući broj sati u mjesecu
A7: Datum početka | D7: =+A12 -> 46082 | G7: Datum kraja | J7: =+EOMONTH(D7,0) -> 46112 | M7: Broj radnih dana | P7: =+NETWORKDAYS(D7,J7,0) -> 22 | R7: Broj radnih sati | V7: 8 | X7: Mogući broj sati u mjesecu | AC7: =+P7*V7 -> 176
A9: =+YEAR(A12) -> 2026 | F9: Vrijeme / Sati nazočnosti na poslu | N9: Vrijeme / Sati nenazočnosti na poslu zbog
A10: Datum | B10: Dan | C10: Početak rada | D10: Završetak rada | E10: Ukupno sati | F10: 1.smjena | G10: 2.smjena | H10: Noćni rad | I10: Rad Nedjeljom | J10: Rad praznikom | K10: Prekovremeni rad | L10: Vrijeme terenskog rada | M10: Vrijeme pripravnosti | N10: Dnevni odmor | O10: Tjedni odmor | P10: Godišnji odmor | Q10: Neradni dani - blagdani | R10: Privremena nesposobnost za rad - do 42 dana | S10: Privremena nesposobnost za rad - iznad 42 dana | T10: Porodiljni - rodiljni dopust | U10: Plaćeni dopust - odsustnost s rada | V10: Sati očinskog dopusta i dopusta drugog posvojitelja | W10: Neplaćeni dopust - pruž.osobne skrbi | X10: Neplaćen dopust kandidata - razno | Y10: Neplaćeni dopust - na zahtjev radnika | Z10: Krivnje radnika - ne obavlja ugovorene poslove | AA10: Krivnja poslodavca - zastoj | AB10: Vojna obveza ili služenje u ugovornoj pričuvi | AC10: štrajka | AD10: isključenja s rada - lockout | AE10: KONTROLNI ZBROJ
A12: 46082 | B12: =+TEXT(A12,"DDD") -> ned | E12: =+D12-C12 -> 0 | AE12: =SUM(F12:AD12) -> 0
A13: =+A12+1 -> 46083 | B13: =+TEXT(A13,"DDD") -> pon | E13: =+D13-C13 -> 0 | AE13: =SUM(F13:AD13) -> 0
A14: =+A13+1 -> 46084 | B14: =+TEXT(A14,"DDD") -> uto | E14: =+D14-C14 -> 0 | AE14: =SUM(F14:AD14) -> 0
A15: =+A14+1 -> 46085 | B15: =+TEXT(A15,"DDD") -> sri | E15: =+D15-C15 -> 0 | AE15: =SUM(F15:AD15) -> 0
A16: =+A15+1 -> 46086 | B16: =+TEXT(A16,"DDD") -> čet | E16: =+D16-C16 -> 0 | AE16: =SUM(F16:AD16) -> 0
A17: =+A16+1 -> 46087 | B17: =+TEXT(A17,"DDD") -> pet | E17: =+D17-C17 -> 0 | AE17: =SUM(F17:AD17) -> 0
A18: =+A17+1 -> 46088 | B18: =+TEXT(A18,"DDD") -> sub | E18: =+D18-C18 -> 0 | AE18: =SUM(F18:AD18) -> 0
A19: =+A18+1 -> 46089 | B19: =+TEXT(A19,"DDD") -> ned | E19: =+D19-C19 -> 0 | AE19: =SUM(F19:AD19) -> 0
A20: =+A19+1 -> 46090 | B20: =+TEXT(A20,"DDD") -> pon | E20: =+D20-C20 -> 0 | AE20: =SUM(F20:AD20) -> 0
A21: =+A20+1 -> 46091 | B21: =+TEXT(A21,"DDD") -> uto | E21: =+D21-C21 -> 0 | AE21: =SUM(F21:AD21) -> 0
A22: =+A21+1 -> 46092 | B22: =+TEXT(A22,"DDD") -> sri | E22: =+D22-C22 -> 0 | AE22: =SUM(F22:AD22) -> 0
A23: =+A22+1 -> 46093 | B23: =+TEXT(A23,"DDD") -> čet | E23: =+D23-C23 -> 0 | AE23: =SUM(F23:AD23) -> 0
A24: =+A23+1 -> 46094 | B24: =+TEXT(A24,"DDD") -> pet | E24: =+D24-C24 -> 0 | AE24: =SUM(F24:AD24) -> 0
... A42: =+A41+1 -> 46112 | B42: =+TEXT(A42,"DDD") -> uto | E42: =+D42-C42 -> 0 | AE42: =SUM(F42:AD42) -> 0
A44: *** | B44: *** | C44: *** | D44: *** | E44: =SUM(E12:E43) -> 0 | F44: =SUM(F12:F43) -> 0 | G44: =SUM(G12:G43) -> 0 | H44: =SUM(H12:H43) -> 0 | I44: =SUM(I12:I43) -> 0 | J44: =SUM(J12:J43) -> 0 | K44: =SUM(K12:K43) -> 0 | L44: =SUM(L12:L43) -> 0 | ... AD44: =SUM(AD12:AD43) -> 0 | AE44: ***
E45: =+E10 -> Ukupno sati | F45: =+F10 -> 1.smjena | G45: =+G10 -> 2.smjena | H45: =+H10 -> Noćni rad | I45: =+I10 -> Rad Nedjeljom | J45: =+J10 -> Rad praznikom | K45: =+K10 -> Prekovremeni rad | L45: =+L10 -> Vrijeme terenskog rada | ... AE45: =+AE10 -> KONTROLNI ZBROJ
A46: Broj sati nazočnosti na poslu: | G46: =+SUM(F44:M44) -> 0 | J46: Ukupan broj sati : | P46: =+G46+G47 -> 0 | S46: Postotak minulog rada:
A47: Broj sati NEnazočnosti na poslu: | G47: =+SUM(P44:AD44) -> 0

Sheet 04
A1: EVIDENCIJA O RADNOM VREMENU ZAPOSLENIKA
A2: RAD U SMJENAMA ? | E2: =+'01'!E2 -> NE
A3: Raspored 1.smjena | E3: 6 | F3: 14 | G3: Ime i prezime radnika: | M3: =+Podaci!B18 -> MARICA MARINČIĆ | S3: NAZIV TVRTKE I OIB:
A4: Raspored 2.smjena | E4: 14 | F4: 22 | G4: OIB radnika: | M4: =+Podaci!B19 -> 78945612389 | S4: =+Podaci!B4 -> TVRTKA ABC D.O.O.
A5: Noćni rad | E5: 22 | F5: 6 | G5: E-MAIL radnika: | M5: =+Podaci!B31 -> info@metro-servis.hr | S5: =+Podaci!B5 -> 12345678910
A6: MJESEC | D6: =+MONTH(D7) -> 4 | G6: GODINA | J6: =+YEAR(J7) -> 2026 | R6: Broj radnih sati | V6: 7 + 5 | X6: Mogući broj sati u mjesecu
A7: Datum početka | D7: =+A12 -> 46113 | G7: Datum kraja | J7: =+EOMONTH(D7,0) -> 46142 | M7: Broj radnih dana | P7: =+NETWORKDAYS(D7,J7,0) -> 22 | R7: Broj radnih sati | V7: 8 | X7: Mogući broj sati u mjesecu | AC7: =+P7*V7 -> 176
A9: =+YEAR(A12) -> 2026 | F9: Vrijeme / Sati nazočnosti na poslu | N9: Vrijeme / Sati nenazočnosti na poslu zbog
A10: Datum | B10: Dan | C10: Početak rada | D10: Završetak rada | E10: Ukupno sati | F10: 1.smjena | G10: 2.smjena | H10: Noćni rad | I10: Rad Nedjeljom | J10: Rad praznikom | K10: Prekovremeni rad | L10: Vrijeme terenskog rada | M10: Vrijeme pripravnosti | N10: Dnevni odmor | O10: Tjedni odmor | P10: Godišnji odmor | Q10: Neradni dani - blagdani | R10: Privremena nesposobnost za rad - do 42 dana | S10: Privremena nesposobnost za rad - iznad 42 dana | T10: Porodiljni - rodiljni dopust | U10: Plaćeni dopust - odsustnost s rada | V10: Sati očinskog dopusta i dopusta drugog posvojitelja | W10: Neplaćeni dopust - pruž.osobne skrbi | X10: Neplaćen dopust kandidata - razno | Y10: Neplaćeni dopust - na zahtjev radnika | Z10: Krivnje radnika - ne obavlja ugovorene poslove | AA10: Krivnja poslodavca - zastoj | AB10: Vojna obveza ili služenje u ugovornoj pričuvi | AC10: štrajka | AD10: isključenja s rada - lockout | AE10: KONTROLNI ZBROJ
A12: 46113 | B12: =+TEXT(A12,"DDD") -> sri | E12: =+D12-C12 -> 0 | AE12: =SUM(F12:AD12) -> 0
A13: =+A12+1 -> 46114 | B13: =+TEXT(A13,"DDD") -> čet | E13: =+D13-C13 -> 0 | AE13: =SUM(F13:AD13) -> 0
A14: =+A13+1 -> 46115 | B14: =+TEXT(A14,"DDD") -> pet | E14: =+D14-C14 -> 0 | AE14: =SUM(F14:AD14) -> 0
A15: =+A14+1 -> 46116 | B15: =+TEXT(A15,"DDD") -> sub | E15: =+D15-C15 -> 0 | AE15: =SUM(F15:AD15) -> 0
A16: =+A15+1 -> 46117 | B16: =+TEXT(A16,"DDD") -> ned | E16: =+D16-C16 -> 0 | AE16: =SUM(F16:AD16) -> 0
A17: =+A16+1 -> 46118 | B17: =+TEXT(A17,"DDD") -> pon | E17: =+D17-C17 -> 0 | AE17: =SUM(F17:AD17) -> 0
A18: =+A17+1 -> 46119 | B18: =+TEXT(A18,"DDD") -> uto | E18: =+D18-C18 -> 0 | AE18: =SUM(F18:AD18) -> 0
A19: =+A18+1 -> 46120 | B19: =+TEXT(A19,"DDD") -> sri | E19: =+D19-C19 -> 0 | AE19: =SUM(F19:AD19) -> 0
A20: =+A19+1 -> 46121 | B20: =+TEXT(A20,"DDD") -> čet | E20: =+D20-C20 -> 0 | AE20: =SUM(F20:AD20) -> 0
A21: =+A20+1 -> 46122 | B21: =+TEXT(A21,"DDD") -> pet | E21: =+D21-C21 -> 0 | AE21: =SUM(F21:AD21) -> 0
A22: =+A21+1 -> 46123 | B22: =+TEXT(A22,"DDD") -> sub | E22: =+D22-C22 -> 0 | AE22: =SUM(F22:AD22) -> 0
A23: =+A22+1 -> 46124 | B23: =+TEXT(A23,"DDD") -> ned | E23: =+D23-C23 -> 0 | AE23: =SUM(F23:AD23) -> 0
A24: =+A23+1 -> 46125 | B24: =+TEXT(A24,"DDD") -> pon | E24: =+D24-C24 -> 0 | AE24: =SUM(F24:AD24) -> 0
... A41: =+A40+1 -> 46142 | B41: =+TEXT(A41,"DDD") -> čet | E41: =+D41-C41 -> 0 | AE41: =SUM(F41:AD41) -> 0
A44: *** | B44: *** | C44: *** | D44: *** | E44: =SUM(E12:E43) -> 0 | F44: =SUM(F12:F43) -> 0 | G44: =SUM(G12:G43) -> 0 | H44: =SUM(H12:H43) -> 0 | I44: =SUM(I12:I43) -> 0 | J44: =SUM(J12:J43) -> 0 | K44: =SUM(K12:K43) -> 0 | L44: =SUM(L12:L43) -> 0 | ... AD44: =SUM(AD12:AD43) -> 0 | AE44: ***
E45: =+E10 -> Ukupno sati | F45: =+F10 -> 1.smjena | G45: =+G10 -> 2.smjena | H45: =+H10 -> Noćni rad | I45: =+I10 -> Rad Nedjeljom | J45: =+J10 -> Rad praznikom | K45: =+K10 -> Prekovremeni rad | L45: =+L10 -> Vrijeme terenskog rada | ... AE45: =+AE10 -> KONTROLNI ZBROJ
A46: Broj sati nazočnosti na poslu: | G46: =+SUM(F44:M44) -> 0 | J46: Ukupan broj sati : | P46: =+G46+G47 -> 0 | S46: Postotak minulog rada:
A47: Broj sati NEnazočnosti na poslu: | G47: =+SUM(P44:AD44) -> 0

Sheet 05
A1: EVIDENCIJA O RADNOM VREMENU ZAPOSLENIKA
A2: RAD U SMJENAMA ? | E2: =+'01'!E2 -> NE
A3: Raspored 1.smjena | E3: 6 | F3: 14 | G3: Ime i prezime radnika: | M3: =+Podaci!B18 -> MARICA MARINČIĆ | S3: NAZIV TVRTKE I OIB:
A4: Raspored 2.smjena | E4: 14 | F4: 22 | G4: OIB radnika: | M4: =+Podaci!B19 -> 78945612389 | S4: =+Podaci!B4 -> TVRTKA ABC D.O.O.
A5: Noćni rad | E5: 22 | F5: 6 | G5: E-MAIL radnika: | M5: =+Podaci!B31 -> info@metro-servis.hr | S5: =+Podaci!B5 -> 12345678910
A6: MJESEC | D6: =+MONTH(D7) -> 5 | G6: GODINA | J6: =+YEAR(J7) -> 2026 | R6: Broj radnih sati | V6: 7 + 5 | X6: Mogući broj sati u mjesecu
A7: Datum početka | D7: =+A12 -> 46143 | G7: Datum kraja | J7: =+EOMONTH(D7,0) -> 46173 | M7: Broj radnih dana | P7: =+NETWORKDAYS(D7,J7,0) -> 21 | R7: Broj radnih sati | V7: 8 | X7: Mogući broj sati u mjesecu | AC7: =+P7*V7 -> 168
A9: =+YEAR(A12) -> 2026 | F9: Vrijeme / Sati nazočnosti na poslu | N9: Vrijeme / Sati nenazočnosti na poslu zbog
A10: Datum | B10: Dan | C10: Početak rada | D10: Završetak rada | E10: Ukupno sati | F10: 1.smjena | G10: 2.smjena | H10: Noćni rad | I10: Rad Nedjeljom | J10: Rad praznikom | K10: Prekovremeni rad | L10: Vrijeme terenskog rada | M10: Vrijeme pripravnosti | N10: Dnevni odmor | O10: Tjedni odmor | P10: Godišnji odmor | Q10: Neradni dani - blagdani | R10: Privremena nesposobnost za rad - do 42 dana | S10: Privremena nesposobnost za rad - iznad 42 dana | T10: Porodiljni - rodiljni dopust | U10: Plaćeni dopust - odsustnost s rada | V10: Sati očinskog dopusta i dopusta drugog posvojitelja | W10: Neplaćeni dopust - pruž.osobne skrbi | X10: Neplaćen dopust kandidata - razno | Y10: Neplaćeni dopust - na zahtjev radnika | Z10: Krivnje radnika - ne obavlja ugovorene poslove | AA10: Krivnja poslodavca - zastoj | AB10: Vojna obveza ili služenje u ugovornoj pričuvi | AC10: štrajka | AD10: isključenja s rada - lockout | AE10: KONTROLNI ZBROJ
A12: 46143 | B12: =+TEXT(A12,"DDD") -> pet | E12: =+D12-C12 -> 0 | AE12: =SUM(F12:AD12) -> 0
A13: =+A12+1 -> 46144 | B13: =+TEXT(A13,"DDD") -> sub | E13: =+D13-C13 -> 0 | AE13: =SUM(F13:AD13) -> 0
A14: =+A13+1 -> 46145 | B14: =+TEXT(A14,"DDD") -> ned | E14: =+D14-C14 -> 0 | AE14: =SUM(F14:AD14) -> 0
A15: =+A14+1 -> 46146 | B15: =+TEXT(A15,"DDD") -> pon | E15: =+D15-C15 -> 0 | AE15: =SUM(F15:AD15) -> 0
A16: =+A15+1 -> 46147 | B16: =+TEXT(A16,"DDD") -> uto | E16: =+D16-C16 -> 0 | AE16: =SUM(F16:AD16) -> 0
A17: =+A16+1 -> 46148 | B17: =+TEXT(A17,"DDD") -> sri | E17: =+D17-C17 -> 0 | AE17: =SUM(F17:AD17) -> 0
A18: =+A17+1 -> 46149 | B18: =+TEXT(A18,"DDD") -> čet | E18: =+D18-C18 -> 0 | AE18: =SUM(F18:AD18) -> 0
A19: =+A18+1 -> 46150 | B19: =+TEXT(A19,"DDD") -> pet | E19: =+D19-C19 -> 0 | AE19: =SUM(F19:AD19) -> 0
A20: =+A19+1 -> 46151 | B20: =+TEXT(A20,"DDD") -> sub | E20: =+D20-C20 -> 0 | AE20: =SUM(F20:AD20) -> 0
A21: =+A20+1 -> 46152 | B21: =+TEXT(A21,"DDD") -> ned | E21: =+D21-C21 -> 0 | AE21: =SUM(F21:AD21) -> 0
A22: =+A21+1 -> 46153 | B22: =+TEXT(A22,"DDD") -> pon | E22: =+D22-C22 -> 0 | AE22: =SUM(F22:AD22) -> 0
A23: =+A22+1 -> 46154 | B23: =+TEXT(A23,"DDD") -> uto | E23: =+D23-C23 -> 0 | AE23: =SUM(F23:AD23) -> 0
A24: =+A23+1 -> 46155 | B24: =+TEXT(A24,"DDD") -> sri | E24: =+D24-C24 -> 0 | AE24: =SUM(F24:AD24) -> 0
... A42: =+A41+1 -> 46173 | B42: =+TEXT(A42,"DDD") -> ned | E42: =+D42-C42 -> 0 | AE42: =SUM(F42:AD42) -> 0
A44: *** | B44: *** | C44: *** | D44: *** | E44: =SUM(E12:E43) -> 0 | F44: =SUM(F12:F43) -> 0 | G44: =SUM(G12:G43) -> 0 | H44: =SUM(H12:H43) -> 0 | I44: =SUM(I12:I43) -> 0 | J44: =SUM(J12:J43) -> 0 | K44: =SUM(K12:K43) -> 0 | L44: =SUM(L12:L43) -> 0 | ... AD44: =SUM(AD12:AD43) -> 0 | AE44: ***
E45: =+E10 -> Ukupno sati | F45: =+F10 -> 1.smjena | G45: =+G10 -> 2.smjena | H45: =+H10 -> Noćni rad | I45: =+I10 -> Rad Nedjeljom | J45: =+J10 -> Rad praznikom | K45: =+K10 -> Prekovremeni rad | L45: =+L10 -> Vrijeme terenskog rada | ... AE45: =+AE10 -> KONTROLNI ZBROJ
A46: Broj sati nazočnosti na poslu: | G46: =+SUM(F44:M44) -> 0 | J46: Ukupan broj sati : | P46: =+G46+G47 -> 0 | S46: Postotak minulog rada:
A47: Broj sati NEnazočnosti na poslu: | G47: =+SUM(P44:AD44) -> 0

Sheet 06
A1: EVIDENCIJA O RADNOM VREMENU ZAPOSLENIKA
A2: RAD U SMJENAMA ? | E2: =+'01'!E2 -> NE
A3: Raspored 1.smjena | E3: 6 | F3: 14 | G3: Ime i prezime radnika: | M3: =+Podaci!B18 -> MARICA MARINČIĆ | S3: NAZIV TVRTKE I OIB:
A4: Raspored 2.smjena | E4: 14 | F4: 22 | G4: OIB radnika: | M4: =+Podaci!B19 -> 78945612389 | S4: =+Podaci!B4 -> TVRTKA ABC D.O.O.
A5: Noćni rad | E5: 22 | F5: 6 | G5: E-MAIL radnika: | M5: =+Podaci!B31 -> info@metro-servis.hr | S5: =+Podaci!B5 -> 12345678910
A6: MJESEC | D6: =+MONTH(D7) -> 6 | G6: GODINA | J6: =+YEAR(J7) -> 2026 | R6: Broj radnih sati | V6: 7 + 5 | X6: Mogući broj sati u mjesecu
A7: Datum početka | D7: =+A12 -> 46174 | G7: Datum kraja | J7: =+EOMONTH(D7,0) -> 46203 | M7: Broj radnih dana | P7: =+NETWORKDAYS(D7,J7,0) -> 22 | R7: Broj radnih sati | V7: 8 | X7: Mogući broj sati u mjesecu | AC7: =+P7*V7 -> 176
A9: =+YEAR(A12) -> 2026 | F9: Vrijeme / Sati nazočnosti na poslu | N9: Vrijeme / Sati nenazočnosti na poslu zbog
A10: Datum | B10: Dan | C10: Početak rada | D10: Završetak rada | E10: Ukupno sati | F10: 1.smjena | G10: 2.smjena | H10: Noćni rad | I10: Rad Nedjeljom | J10: Rad praznikom | K10: Prekovremeni rad | L10: Vrijeme terenskog rada | M10: Vrijeme pripravnosti | N10: Dnevni odmor | O10: Tjedni odmor | P10: Godišnji odmor | Q10: Neradni dani - blagdani | R10: Privremena nesposobnost za rad - do 42 dana | S10: Privremena nesposobnost za rad - iznad 42 dana | T10: Porodiljni - rodiljni dopust | U10: Plaćeni dopust - odsustnost s rada | V10: Sati očinskog dopusta i dopusta drugog posvojitelja | W10: Neplaćeni dopust - pruž.osobne skrbi | X10: Neplaćen dopust kandidata - razno | Y10: Neplaćeni dopust - na zahtjev radnika | Z10: Krivnje radnika - ne obavlja ugovorene poslove | AA10: Krivnja poslodavca - zastoj | AB10: Vojna obveza ili služenje u ugovornoj pričuvi | AC10: štrajka | AD10: isključenja s rada - lockout | AE10: KONTROLNI ZBROJ
A12: 46174 | B12: =+TEXT(A12,"DDD") -> pon | E12: =+D12-C12 -> 0 | AE12: =SUM(F12:AD12) -> 0
A13: =+A12+1 -> 46175 | B13: =+TEXT(A13,"DDD") -> uto | E13: =+D13-C13 -> 0 | AE13: =SUM(F13:AD13) -> 0
A14: =+A13+1 -> 46176 | B14: =+TEXT(A14,"DDD") -> sri | E14: =+D14-C14 -> 0 | AE14: =SUM(F14:AD14) -> 0
A15: =+A14+1 -> 46177 | B15: =+TEXT(A15,"DDD") -> čet | E15: =+D15-C15 -> 0 | AE15: =SUM(F15:AD15) -> 0
A16: =+A15+1 -> 46178 | B16: =+TEXT(A16,"DDD") -> pet | E16: =+D16-C16 -> 0 | AE16: =SUM(F16:AD16) -> 0
A17: =+A16+1 -> 46179 | B17: =+TEXT(A17,"DDD") -> sub | E17: =+D17-C17 -> 0 | AE17: =SUM(F17:AD17) -> 0
A18: =+A17+1 -> 46180 | B18: =+TEXT(A18,"DDD") -> ned | E18: =+D18-C18 -> 0 | AE18: =SUM(F18:AD18) -> 0
A19: =+A18+1 -> 46181 | B19: =+TEXT(A19,"DDD") -> pon | E19: =+D19-C19 -> 0 | AE19: =SUM(F19:AD19) -> 0
A20: =+A19+1 -> 46182 | B20: =+TEXT(A20,"DDD") -> uto | E20: =+D20-C20 -> 0 | AE20: =SUM(F20:AD20) -> 0
A21: =+A20+1 -> 46183 | B21: =+TEXT(A21,"DDD") -> sri | E21: =+D21-C21 -> 0 | AE21: =SUM(F21:AD21) -> 0
A22: =+A21+1 -> 46184 | B22: =+TEXT(A22,"DDD") -> čet | E22: =+D22-C22 -> 0 | AE22: =SUM(F22:AD22) -> 0
A23: =+A22+1 -> 46185 | B23: =+TEXT(A23,"DDD") -> pet | E23: =+D23-C23 -> 0 | AE23: =SUM(F23:AD23) -> 0
A24: =+A23+1 -> 46186 | B24: =+TEXT(A24,"DDD") -> sub | E24: =+D24-C24 -> 0 | AE24: =SUM(F24:AD24) -> 0
... A41: =+A40+1 -> 46203 | B41: =+TEXT(A41,"DDD") -> uto | E41: =+D41-C41 -> 0 | AE41: =SUM(F41:AD41) -> 0
A44: *** | B44: *** | C44: *** | D44: *** | E44: =SUM(E12:E43) -> 0 | F44: =SUM(F12:F43) -> 0 | G44: =SUM(G12:G43) -> 0 | H44: =SUM(H12:H43) -> 0 | I44: =SUM(I12:I43) -> 0 | J44: =SUM(J12:J43) -> 0 | K44: =SUM(K12:K43) -> 0 | L44: =SUM(L12:L43) -> 0 | ... AD44: =SUM(AD12:AD43) -> 0 | AE44: ***
E45: =+E10 -> Ukupno sati | F45: =+F10 -> 1.smjena | G45: =+G10 -> 2.smjena | H45: =+H10 -> Noćni rad | I45: =+I10 -> Rad Nedjeljom | J45: =+J10 -> Rad praznikom | K45: =+K10 -> Prekovremeni rad | L45: =+L10 -> Vrijeme terenskog rada | ... AE45: =+AE10 -> KONTROLNI ZBROJ
A46: Broj sati nazočnosti na poslu: | G46: =+SUM(F44:M44) -> 0 | J46: Ukupan broj sati : | P46: =+G46+G47 -> 0 | S46: Postotak minulog rada:
A47: Broj sati NEnazočnosti na poslu: | G47: =+SUM(P44:AD44) -> 0

Sheet 07
A1: EVIDENCIJA O RADNOM VREMENU ZAPOSLENIKA
A2: RAD U SMJENAMA ? | E2: =+'01'!E2 -> NE
A3: Raspored 1.smjena | E3: 6 | F3: 14 | G3: Ime i prezime radnika: | M3: =+Podaci!B18 -> MARICA MARINČIĆ | S3: NAZIV TVRTKE I OIB:
A4: Raspored 2.smjena | E4: 14 | F4: 22 | G4: OIB radnika: | M4: =+Podaci!B19 -> 78945612389 | S4: =+Podaci!B4 -> TVRTKA ABC D.O.O.
A5: Noćni rad | E5: 22 | F5: 6 | G5: E-MAIL radnika: | M5: =+Podaci!B31 -> info@metro-servis.hr | S5: =+Podaci!B5 -> 12345678910
A6: MJESEC | D6: =+MONTH(D7) -> 7 | G6: GODINA | J6: =+YEAR(J7) -> 2026 | R6: Broj radnih sati | V6: 7 + 5 | X6: Mogući broj sati u mjesecu
A7: Datum početka | D7: =+A12 -> 46204 | G7: Datum kraja | J7: =+EOMONTH(D7,0) -> 46234 | M7: Broj radnih dana | P7: =+NETWORKDAYS(D7,J7,0) -> 23 | R7: Broj radnih sati | V7: 8 | X7: Mogući broj sati u mjesecu | AC7: =+P7*V7 -> 184
A9: =+YEAR(A12) -> 2026 | F9: Vrijeme / Sati nazočnosti na poslu | N9: Vrijeme / Sati nenazočnosti na poslu zbog
A10: Datum | B10: Dan | C10: Početak rada | D10: Završetak rada | E10: Ukupno sati | F10: 1.smjena | G10: 2.smjena | H10: Noćni rad | I10: Rad Nedjeljom | J10: Rad praznikom | K10: Prekovremeni rad | L10: Vrijeme terenskog rada | M10: Vrijeme pripravnosti | N10: Dnevni odmor | O10: Tjedni odmor | P10: Godišnji odmor | Q10: Neradni dani - blagdani | R10: Privremena nesposobnost za rad - do 42 dana | S10: Privremena nesposobnost za rad - iznad 42 dana | T10: Porodiljni - rodiljni dopust | U10: Plaćeni dopust - odsustnost s rada | V10: Sati očinskog dopusta i dopusta drugog posvojitelja | W10: Neplaćeni dopust - pruž.osobne skrbi | X10: Neplaćen dopust kandidata - razno | Y10: Neplaćeni dopust - na zahtjev radnika | Z10: Krivnje radnika - ne obavlja ugovorene poslove | AA10: Krivnja poslodavca - zastoj | AB10: Vojna obveza ili služenje u ugovornoj pričuvi | AC10: štrajka | AD10: isključenja s rada - lockout | AE10: KONTROLNI ZBROJ
A12: 46204 | B12: =+TEXT(A12,"DDD") -> sri | E12: =+D12-C12 -> 0 | AE12: =SUM(F12:AD12) -> 0
A13: =+A12+1 -> 46205 | B13: =+TEXT(A13,"DDD") -> čet | E13: =+D13-C13 -> 0 | AE13: =SUM(F13:AD13) -> 0
A14: =+A13+1 -> 46206 | B14: =+TEXT(A14,"DDD") -> pet | E14: =+D14-C14 -> 0 | AE14: =SUM(F14:AD14) -> 0
A15: =+A14+1 -> 46207 | B15: =+TEXT(A15,"DDD") -> sub | E15: =+D15-C15 -> 0 | AE15: =SUM(F15:AD15) -> 0
A16: =+A15+1 -> 46208 | B16: =+TEXT(A16,"DDD") -> ned | E16: =+D16-C16 -> 0 | AE16: =SUM(F16:AD16) -> 0
A17: =+A16+1 -> 46209 | B17: =+TEXT(A17,"DDD") -> pon | E17: =+D17-C17 -> 0 | AE17: =SUM(F17:AD17) -> 0
A18: =+A17+1 -> 46210 | B18: =+TEXT(A18,"DDD") -> uto | E18: =+D18-C18 -> 0 | AE18: =SUM(F18:AD18) -> 0
A19: =+A18+1 -> 46211 | B19: =+TEXT(A19,"DDD") -> sri | E19: =+D19-C19 -> 0 | AE19: =SUM(F19:AD19) -> 0
A20: =+A19+1 -> 46212 | B20: =+TEXT(A20,"DDD") -> čet | E20: =+D20-C20 -> 0 | AE20: =SUM(F20:AD20) -> 0
A21: =+A20+1 -> 46213 | B21: =+TEXT(A21,"DDD") -> pet | E21: =+D21-C21 -> 0 | AE21: =SUM(F21:AD21) -> 0
A22: =+A21+1 -> 46214 | B22: =+TEXT(A22,"DDD") -> sub | E22: =+D22-C22 -> 0 | AE22: =SUM(F22:AD22) -> 0
A23: =+A22+1 -> 46215 | B23: =+TEXT(A23,"DDD") -> ned | E23: =+D23-C23 -> 0 | AE23: =SUM(F23:AD23) -> 0
A24: =+A23+1 -> 46216 | B24: =+TEXT(A24,"DDD") -> pon | E24: =+D24-C24 -> 0 | AE24: =SUM(F24:AD24) -> 0
... A42: =+A41+1 -> 46234 | B42: =+TEXT(A42,"DDD") -> pet | E42: =+D42-C42 -> 0 | AE42: =SUM(F42:AD42) -> 0
A44: *** | B44: *** | C44: *** | D44: *** | E44: =SUM(E12:E43) -> 0 | F44: =SUM(F12:F43) -> 0 | G44: =SUM(G12:G43) -> 0 | H44: =SUM(H12:H43) -> 0 | I44: =SUM(I12:I43) -> 0 | J44: =SUM(J12:J43) -> 0 | K44: =SUM(K12:K43) -> 0 | L44: =SUM(L12:L43) -> 0 | ... AD44: =SUM(AD12:AD43) -> 0 | AE44: ***
E45: =+E10 -> Ukupno sati | F45: =+F10 -> 1.smjena | G45: =+G10 -> 2.smjena | H45: =+H10 -> Noćni rad | I45: =+I10 -> Rad Nedjeljom | J45: =+J10 -> Rad praznikom | K45: =+K10 -> Prekovremeni rad | L45: =+L10 -> Vrijeme terenskog rada | ... AE45: =+AE10 -> KONTROLNI ZBROJ
A46: Broj sati nazočnosti na poslu: | G46: =+SUM(F44:M44) -> 0 | J46: Ukupan broj sati : | P46: =+G46+G47 -> 0 | S46: Postotak minulog rada:
A47: Broj sati NEnazočnosti na poslu: | G47: =+SUM(P44:AD44) -> 0

Sheet 08
A1: EVIDENCIJA O RADNOM VREMENU ZAPOSLENIKA
A2: RAD U SMJENAMA ? | E2: =+'01'!E2 -> NE
A3: Raspored 1.smjena | E3: 6 | F3: 14 | G3: Ime i prezime radnika: | M3: =+Podaci!B18 -> MARICA MARINČIĆ | S3: NAZIV TVRTKE I OIB:
A4: Raspored 2.smjena | E4: 14 | F4: 22 | G4: OIB radnika: | M4: =+Podaci!B19 -> 78945612389 | S4: =+Podaci!B4 -> TVRTKA ABC D.O.O.
A5: Noćni rad | E5: 22 | F5: 6 | G5: E-MAIL radnika: | M5: =+Podaci!B31 -> info@metro-servis.hr | S5: =+Podaci!B5 -> 12345678910
A6: MJESEC | D6: =+MONTH(D7) -> 8 | G6: GODINA | J6: =+YEAR(J7) -> 2026 | R6: Broj radnih sati | V6: 7 + 5 | X6: Mogući broj sati u mjesecu
A7: Datum početka | D7: =+A12 -> 46235 | G7: Datum kraja | J7: =+EOMONTH(D7,0) -> 46265 | M7: Broj radnih dana | P7: =+NETWORKDAYS(D7,J7,0) -> 21 | R7: Broj radnih sati | V7: 8 | X7: Mogući broj sati u mjesecu | AC7: =+P7*V7 -> 168
A9: =+YEAR(A12) -> 2026 | F9: Vrijeme / Sati nazočnosti na poslu | N9: Vrijeme / Sati nenazočnosti na poslu zbog
A10: Datum | B10: Dan | C10: Početak rada | D10: Završetak rada | E10: Ukupno sati | F10: 1.smjena | G10: 2.smjena | H10: Noćni rad | I10: Rad Nedjeljom | J10: Rad praznikom | K10: Prekovremeni rad | L10: Vrijeme terenskog rada | M10: Vrijeme pripravnosti | N10: Dnevni odmor | O10: Tjedni odmor | P10: Godišnji odmor | Q10: Neradni dani - blagdani | R10: Privremena nesposobnost za rad - do 42 dana | S10: Privremena nesposobnost za rad - iznad 42 dana | T10: Porodiljni - rodiljni dopust | U10: Plaćeni dopust - odsustnost s rada | V10: Sati očinskog dopusta i dopusta drugog posvojitelja | W10: Neplaćeni dopust - pruž.osobne skrbi | X10: Neplaćen dopust kandidata - razno | Y10: Neplaćeni dopust - na zahtjev radnika | Z10: Krivnje radnika - ne obavlja ugovorene poslove | AA10: Krivnja poslodavca - zastoj | AB10: Vojna obveza ili služenje u ugovornoj pričuvi | AC10: štrajka | AD10: isključenja s rada - lockout | AE10: KONTROLNI ZBROJ
A12: 46235 | B12: =+TEXT(A12,"DDD") -> sub | E12: =+D12-C12 -> 0 | AE12: =SUM(F12:AD12) -> 0
A13: =+A12+1 -> 46236 | B13: =+TEXT(A13,"DDD") -> ned | E13: =+D13-C13 -> 0 | AE13: =SUM(F13:AD13) -> 0
A14: =+A13+1 -> 46237 | B14: =+TEXT(A14,"DDD") -> pon | E14: =+D14-C14 -> 0 | AE14: =SUM(F14:AD14) -> 0
A15: =+A14+1 -> 46238 | B15: =+TEXT(A15,"DDD") -> uto | E15: =+D15-C15 -> 0 | AE15: =SUM(F15:AD15) -> 0
A16: =+A15+1 -> 46239 | B16: =+TEXT(A16,"DDD") -> sri | E16: =+D16-C16 -> 0 | AE16: =SUM(F16:AD16) -> 0
A17: =+A16+1 -> 46240 | B17: =+TEXT(A17,"DDD") -> čet | E17: =+D17-C17 -> 0 | AE17: =SUM(F17:AD17) -> 0
A18: =+A17+1 -> 46241 | B18: =+TEXT(A18,"DDD") -> pet | E18: =+D18-C18 -> 0 | AE18: =SUM(F18:AD18) -> 0
A19: =+A18+1 -> 46242 | B19: =+TEXT(A19,"DDD") -> sub | E19: =+D19-C19 -> 0 | AE19: =SUM(F19:AD19) -> 0
A20: =+A19+1 -> 46243 | B20: =+TEXT(A20,"DDD") -> ned | E20: =+D20-C20 -> 0 | AE20: =SUM(F20:AD20) -> 0
A21: =+A20+1 -> 46244 | B21: =+TEXT(A21,"DDD") -> pon | E21: =+D21-C21 -> 0 | AE21: =SUM(F21:AD21) -> 0
A22: =+A21+1 -> 46245 | B22: =+TEXT(A22,"DDD") -> uto | E22: =+D22-C22 -> 0 | AE22: =SUM(F22:AD22) -> 0
A23: =+A22+1 -> 46246 | B23: =+TEXT(A23,"DDD") -> sri | E23: =+D23-C23 -> 0 | AE23: =SUM(F23:AD23) -> 0
A24: =+A23+1 -> 46247 | B24: =+TEXT(A24,"DDD") -> čet | E24: =+D24-C24 -> 0 | AE24: =SUM(F24:AD24) -> 0
... A42: =+A41+1 -> 46265 | B42: =+TEXT(A42,"DDD") -> pon | E42: =+D42-C42 -> 0 | AE42: =SUM(F42:AD42) -> 0
A44: *** | B44: *** | C44: *** | D44: *** | E44: =SUM(E12:E43) -> 0 | F44: =SUM(F12:F43) -> 0 | G44: =SUM(G12:G43) -> 0 | H44: =SUM(H12:H43) -> 0 | I44: =SUM(I12:I43) -> 0 | J44: =SUM(J12:J43) -> 0 | K44: =SUM(K12:K43) -> 0 | L44: =SUM(L12:L43) -> 0 | ... AD44: =SUM(AD12:AD43) -> 0 | AE44: ***
E45: =+E10 -> Ukupno sati | F45: =+F10 -> 1.smjena | G45: =+G10 -> 2.smjena | H45: =+H10 -> Noćni rad | I45: =+I10 -> Rad Nedjeljom | J45: =+J10 -> Rad praznikom | K45: =+K10 -> Prekovremeni rad | L45: =+L10 -> Vrijeme terenskog rada | ... AE45: =+AE10 -> KONTROLNI ZBROJ
A46: Broj sati nazočnosti na poslu: | G46: =+SUM(F44:M44) -> 0 | J46: Ukupan broj sati : | P46: =+G46+G47 -> 0 | S46: Postotak minulog rada:
A47: Broj sati NEnazočnosti na poslu: | G47: =+SUM(P44:AD44) -> 0

Sheet 09
A1: EVIDENCIJA O RADNOM VREMENU ZAPOSLENIKA
A2: RAD U SMJENAMA ? | E2: =+'01'!E2 -> NE
A3: Raspored 1.smjena | E3: 6 | F3: 14 | G3: Ime i prezime radnika: | M3: =+Podaci!B18 -> MARICA MARINČIĆ | S3: NAZIV TVRTKE I OIB:
A4: Raspored 2.smjena | E4: 14 | F4: 22 | G4: OIB radnika: | M4: =+Podaci!B19 -> 78945612389 | S4: =+Podaci!B4 -> TVRTKA ABC D.O.O.
A5: Noćni rad | E5: 22 | F5: 6 | G5: E-MAIL radnika: | M5: =+Podaci!B31 -> info@metro-servis.hr | S5: =+Podaci!B5 -> 12345678910
A6: MJESEC | D6: =+MONTH(D7) -> 9 | G6: GODINA | J6: =+YEAR(J7) -> 2026 | R6: Broj radnih sati | V6: 7 + 5 | X6: Mogući broj sati u mjesecu
A7: Datum početka | D7: =+A12 -> 46266 | G7: Datum kraja | J7: =+EOMONTH(D7,0) -> 46295 | M7: Broj radnih dana | P7: =+NETWORKDAYS(D7,J7,0) -> 22 | R7: Broj radnih sati | V7: 8 | X7: Mogući broj sati u mjesecu | AC7: =+P7*V7 -> 176
A9: =+YEAR(A12) -> 2026 | F9: Vrijeme / Sati nazočnosti na poslu | N9: Vrijeme / Sati nenazočnosti na poslu zbog
A10: Datum | B10: Dan | C10: Početak rada | D10: Završetak rada | E10: Ukupno sati | F10: 1.smjena | G10: 2.smjena | H10: Noćni rad | I10: Rad Nedjeljom | J10: Rad praznikom | K10: Prekovremeni rad | L10: Vrijeme terenskog rada | M10: Vrijeme pripravnosti | N10: Dnevni odmor | O10: Tjedni odmor | P10: Godišnji odmor | Q10: Neradni dani - blagdani | R10: Privremena nesposobnost za rad - do 42 dana | S10: Privremena nesposobnost za rad - iznad 42 dana | T10: Porodiljni - rodiljni dopust | U10: Plaćeni dopust - odsustnost s rada | V10: Sati očinskog dopusta i dopusta drugog posvojitelja | W10: Neplaćeni dopust - pruž.osobne skrbi | X10: Neplaćen dopust kandidata - razno | Y10: Neplaćeni dopust - na zahtjev radnika | Z10: Krivnje radnika - ne obavlja ugovorene poslove | AA10: Krivnja poslodavca - zastoj | AB10: Vojna obveza ili služenje u ugovornoj pričuvi | AC10: štrajka | AD10: isključenja s rada - lockout | AE10: KONTROLNI ZBROJ
A12: 46266 | B12: =+TEXT(A12,"DDD") -> uto | E12: =+D12-C12 -> 0 | AE12: =SUM(F12:AD12) -> 0
A13: =+A12+1 -> 46267 | B13: =+TEXT(A13,"DDD") -> sri | E13: =+D13-C13 -> 0 | AE13: =SUM(F13:AD13) -> 0
A14: =+A13+1 -> 46268 | B14: =+TEXT(A14,"DDD") -> čet | E14: =+D14-C14 -> 0 | AE14: =SUM(F14:AD14) -> 0
A15: =+A14+1 -> 46269 | B15: =+TEXT(A15,"DDD") -> pet | E15: =+D15-C15 -> 0 | AE15: =SUM(F15:AD15) -> 0
A16: =+A15+1 -> 46270 | B16: =+TEXT(A16,"DDD") -> sub | E16: =+D16-C16 -> 0 | AE16: =SUM(F16:AD16) -> 0
A17: =+A16+1 -> 46271 | B17: =+TEXT(A17,"DDD") -> ned | E17: =+D17-C17 -> 0 | AE17: =SUM(F17:AD17) -> 0
A18: =+A17+1 -> 46272 | B18: =+TEXT(A18,"DDD") -> pon | E18: =+D18-C18 -> 0 | AE18: =SUM(F18:AD18) -> 0
A19: =+A18+1 -> 46273 | B19: =+TEXT(A19,"DDD") -> uto | E19: =+D19-C19 -> 0 | AE19: =SUM(F19:AD19) -> 0
A20: =+A19+1 -> 46274 | B20: =+TEXT(A20,"DDD") -> sri | E20: =+D20-C20 -> 0 | AE20: =SUM(F20:AD20) -> 0
A21: =+A20+1 -> 46275 | B21: =+TEXT(A21,"DDD") -> čet | E21: =+D21-C21 -> 0 | AE21: =SUM(F21:AD21) -> 0
A22: =+A21+1 -> 46276 | B22: =+TEXT(A22,"DDD") -> pet | E22: =+D22-C22 -> 0 | AE22: =SUM(F22:AD22) -> 0
A23: =+A22+1 -> 46277 | B23: =+TEXT(A23,"DDD") -> sub | E23: =+D23-C23 -> 0 | AE23: =SUM(F23:AD23) -> 0
A24: =+A23+1 -> 46278 | B24: =+TEXT(A24,"DDD") -> ned | E24: =+D24-C24 -> 0 | AE24: =SUM(F24:AD24) -> 0
... A41: =+A40+1 -> 46295 | B41: =+TEXT(A41,"DDD") -> sri | E41: =+D41-C41 -> 0 | AE41: =SUM(F41:AD41) -> 0
A44: *** | B44: *** | C44: *** | D44: *** | E44: =SUM(E12:E43) -> 0 | F44: =SUM(F12:F43) -> 0 | G44: =SUM(G12:G43) -> 0 | H44: =SUM(H12:H43) -> 0 | I44: =SUM(I12:I43) -> 0 | J44: =SUM(J12:J43) -> 0 | K44: =SUM(K12:K43) -> 0 | L44: =SUM(L12:L43) -> 0 | ... AD44: =SUM(AD12:AD43) -> 0 | AE44: ***
E45: =+E10 -> Ukupno sati | F45: =+F10 -> 1.smjena | G45: =+G10 -> 2.smjena | H45: =+H10 -> Noćni rad | I45: =+I10 -> Rad Nedjeljom | J45: =+J10 -> Rad praznikom | K45: =+K10 -> Prekovremeni rad | L45: =+L10 -> Vrijeme terenskog rada | ... AE45: =+AE10 -> KONTROLNI ZBROJ
A46: Broj sati nazočnosti na poslu: | G46: =+SUM(F44:M44) -> 0 | J46: Ukupan broj sati : | P46: =+G46+G47 -> 0 | S46: Postotak minulog rada:
A47: Broj sati NEnazočnosti na poslu: | G47: =+SUM(P44:AD44) -> 0

Sheet 10
A1: EVIDENCIJA O RADNOM VREMENU ZAPOSLENIKA
A2: RAD U SMJENAMA ? | E2: =+'01'!E2 -> NE
A3: Raspored 1.smjena | E3: 6 | F3: 14 | G3: Ime i prezime radnika: | M3: =+Podaci!B18 -> MARICA MARINČIĆ | S3: NAZIV TVRTKE I OIB:
A4: Raspored 2.smjena | E4: 14 | F4: 22 | G4: OIB radnika: | M4: =+Podaci!B19 -> 78945612389 | S4: =+Podaci!B4 -> TVRTKA ABC D.O.O.
A5: Noćni rad | E5: 22 | F5: 6 | G5: E-MAIL radnika: | M5: =+Podaci!B31 -> info@metro-servis.hr | S5: =+Podaci!B5 -> 12345678910
A6: MJESEC | D6: =+MONTH(D7) -> 10 | G6: GODINA | J6: =+YEAR(J7) -> 2026 | R6: Broj radnih sati | V6: 7 + 5 | X6: Mogući broj sati u mjesecu
A7: Datum početka | D7: =+A12 -> 46296 | G7: Datum kraja | J7: =+EOMONTH(D7,0) -> 46326 | M7: Broj radnih dana | P7: =+NETWORKDAYS(D7,J7,0) -> 22 | R7: Broj radnih sati | V7: 8 | X7: Mogući broj sati u mjesecu | AC7: =+P7*V7 -> 176
A9: =+YEAR(A12) -> 2026 | F9: Vrijeme / Sati nazočnosti na poslu | N9: Vrijeme / Sati nenazočnosti na poslu zbog
A10: Datum | B10: Dan | C10: Početak rada | D10: Završetak rada | E10: Ukupno sati | F10: 1.smjena | G10: 2.smjena | H10: Noćni rad | I10: Rad Nedjeljom | J10: Rad praznikom | K10: Prekovremeni rad | L10: Vrijeme terenskog rada | M10: Vrijeme pripravnosti | N10: Dnevni odmor | O10: Tjedni odmor | P10: Godišnji odmor | Q10: Neradni dani - blagdani | R10: Privremena nesposobnost za rad - do 42 dana | S10: Privremena nesposobnost za rad - iznad 42 dana | T10: Porodiljni - rodiljni dopust | U10: Plaćeni dopust - odsustnost s rada | V10: Sati očinskog dopusta i dopusta drugog posvojitelja | W10: Neplaćeni dopust - pruž.osobne skrbi | X10: Neplaćen dopust kandidata - razno | Y10: Neplaćeni dopust - na zahtjev radnika | Z10: Krivnje radnika - ne obavlja ugovorene poslove | AA10: Krivnja poslodavca - zastoj | AB10: Vojna obveza ili služenje u ugovornoj pričuvi | AC10: štrajka | AD10: isključenja s rada - lockout | AE10: KONTROLNI ZBROJ
A12: 46296 | B12: =+TEXT(A12,"DDD") -> čet | E12: =+D12-C12 -> 0 | AE12: =SUM(F12:AD12) -> 0
A13: =+A12+1 -> 46297 | B13: =+TEXT(A13,"DDD") -> pet | E13: =+D13-C13 -> 0 | AE13: =SUM(F13:AD13) -> 0
A14: =+A13+1 -> 46298 | B14: =+TEXT(A14,"DDD") -> sub | E14: =+D14-C14 -> 0 | AE14: =SUM(F14:AD14) -> 0
A15: =+A14+1 -> 46299 | B15: =+TEXT(A15,"DDD") -> ned | E15: =+D15-C15 -> 0 | AE15: =SUM(F15:AD15) -> 0
A16: =+A15+1 -> 46300 | B16: =+TEXT(A16,"DDD") -> pon | E16: =+D16-C16 -> 0 | AE16: =SUM(F16:AD16) -> 0
A17: =+A16+1 -> 46301 | B17: =+TEXT(A17,"DDD") -> uto | E17: =+D17-C17 -> 0 | AE17: =SUM(F17:AD17) -> 0
A18: =+A17+1 -> 46302 | B18: =+TEXT(A18,"DDD") -> sri | E18: =+D18-C18 -> 0 | AE18: =SUM(F18:AD18) -> 0
A19: =+A18+1 -> 46303 | B19: =+TEXT(A19,"DDD") -> čet | E19: =+D19-C19 -> 0 | AE19: =SUM(F19:AD19) -> 0
A20: =+A19+1 -> 46304 | B20: =+TEXT(A20,"DDD") -> pet | E20: =+D20-C20 -> 0 | AE20: =SUM(F20:AD20) -> 0
A21: =+A20+1 -> 46305 | B21: =+TEXT(A21,"DDD") -> sub | E21: =+D21-C21 -> 0 | AE21: =SUM(F21:AD21) -> 0
A22: =+A21+1 -> 46306 | B22: =+TEXT(A22,"DDD") -> ned | E22: =+D22-C22 -> 0 | AE22: =SUM(F22:AD22) -> 0
A23: =+A22+1 -> 46307 | B23: =+TEXT(A23,"DDD") -> pon | E23: =+D23-C23 -> 0 | AE23: =SUM(F23:AD23) -> 0
A24: =+A23+1 -> 46308 | B24: =+TEXT(A24,"DDD") -> uto | E24: =+D24-C24 -> 0 | AE24: =SUM(F24:AD24) -> 0
... A42: =+A41+1 -> 46326 | B42: =+TEXT(A42,"DDD") -> sub | E42: =+D42-C42 -> 0 | AE42: =SUM(F42:AD42) -> 0
A44: *** | B44: *** | C44: *** | D44: *** | E44: =SUM(E12:E43) -> 0 | F44: =SUM(F12:F43) -> 0 | G44: =SUM(G12:G43) -> 0 | H44: =SUM(H12:H43) -> 0 | I44: =SUM(I12:I43) -> 0 | J44: =SUM(J12:J43) -> 0 | K44: =SUM(K12:K43) -> 0 | L44: =SUM(L12:L43) -> 0 | ... AD44: =SUM(AD12:AD43) -> 0 | AE44: ***
E45: =+E10 -> Ukupno sati | F45: =+F10 -> 1.smjena | G45: =+G10 -> 2.smjena | H45: =+H10 -> Noćni rad | I45: =+I10 -> Rad Nedjeljom | J45: =+J10 -> Rad praznikom | K45: =+K10 -> Prekovremeni rad | L45: =+L10 -> Vrijeme terenskog rada | ... AE45: =+AE10 -> KONTROLNI ZBROJ
A46: Broj sati nazočnosti na poslu: | G46: =+SUM(F44:M44) -> 0 | J46: Ukupan broj sati : | P46: =+G46+G47 -> 0 | S46: Postotak minulog rada:
A47: Broj sati NEnazočnosti na poslu: | G47: =+SUM(P44:AD44) -> 0

Sheet 11
A1: EVIDENCIJA O RADNOM VREMENU ZAPOSLENIKA
A2: RAD U SMJENAMA ? | E2: =+'01'!E2 -> NE
A3: Raspored 1.smjena | E3: 6 | F3: 14 | G3: Ime i prezime radnika: | M3: =+Podaci!B18 -> MARICA MARINČIĆ | S3: NAZIV TVRTKE I OIB:
A4: Raspored 2.smjena | E4: 14 | F4: 22 | G4: OIB radnika: | M4: =+Podaci!B19 -> 78945612389 | S4: =+Podaci!B4 -> TVRTKA ABC D.O.O.
A5: Noćni rad | E5: 22 | F5: 6 | G5: E-MAIL radnika: | M5: =+Podaci!B31 -> info@metro-servis.hr | S5: =+Podaci!B5 -> 12345678910
A6: MJESEC | D6: =+MONTH(D7) -> 11 | G6: GODINA | J6: =+YEAR(J7) -> 2026 | R6: Broj radnih sati | V6: 7 + 5 | X6: Mogući broj sati u mjesecu
A7: Datum početka | D7: =+A12 -> 46327 | G7: Datum kraja | J7: =+EOMONTH(D7,0) -> 46356 | M7: Broj radnih dana | P7: =+NETWORKDAYS(D7,J7,0) -> 21 | R7: Broj radnih sati | V7: 8 | X7: Mogući broj sati u mjesecu | AC7: =+P7*V7 -> 168
A9: =+YEAR(A12) -> 2026 | F9: Vrijeme / Sati nazočnosti na poslu | N9: Vrijeme / Sati nenazočnosti na poslu zbog
A10: Datum | B10: Dan | C10: Početak rada | D10: Završetak rada | E10: Ukupno sati | F10: 1.smjena | G10: 2.smjena | H10: Noćni rad | I10: Rad Nedjeljom | J10: Rad praznikom | K10: Prekovremeni rad | L10: Vrijeme terenskog rada | M10: Vrijeme pripravnosti | N10: Dnevni odmor | O10: Tjedni odmor | P10: Godišnji odmor | Q10: Neradni dani - blagdani | R10: Privremena nesposobnost za rad - do 42 dana | S10: Privremena nesposobnost za rad - iznad 42 dana | T10: Porodiljni - rodiljni dopust | U10: Plaćeni dopust - odsustnost s rada | V10: Sati očinskog dopusta i dopusta drugog posvojitelja | W10: Neplaćeni dopust - pruž.osobne skrbi | X10: Neplaćen dopust kandidata - razno | Y10: Neplaćeni dopust - na zahtjev radnika | Z10: Krivnje radnika - ne obavlja ugovorene poslove | AA10: Krivnja poslodavca - zastoj | AB10: Vojna obveza ili služenje u ugovornoj pričuvi | AC10: štrajka | AD10: isključenja s rada - lockout | AE10: KONTROLNI ZBROJ
A12: 46327 | B12: =+TEXT(A12,"DDD") -> ned | E12: =+D12-C12 -> 0 | AE12: =SUM(F12:AD12) -> 0
A13: =+A12+1 -> 46328 | B13: =+TEXT(A13,"DDD") -> pon | E13: =+D13-C13 -> 0 | AE13: =SUM(F13:AD13) -> 0
A14: =+A13+1 -> 46329 | B14: =+TEXT(A14,"DDD") -> uto | E14: =+D14-C14 -> 0 | AE14: =SUM(F14:AD14) -> 0
A15: =+A14+1 -> 46330 | B15: =+TEXT(A15,"DDD") -> sri | E15: =+D15-C15 -> 0 | AE15: =SUM(F15:AD15) -> 0
A16: =+A15+1 -> 46331 | B16: =+TEXT(A16,"DDD") -> čet | E16: =+D16-C16 -> 0 | AE16: =SUM(F16:AD16) -> 0
A17: =+A16+1 -> 46332 | B17: =+TEXT(A17,"DDD") -> pet | E17: =+D17-C17 -> 0 | AE17: =SUM(F17:AD17) -> 0
A18: =+A17+1 -> 46333 | B18: =+TEXT(A18,"DDD") -> sub | E18: =+D18-C18 -> 0 | AE18: =SUM(F18:AD18) -> 0
A19: =+A18+1 -> 46334 | B19: =+TEXT(A19,"DDD") -> ned | E19: =+D19-C19 -> 0 | AE19: =SUM(F19:AD19) -> 0
A20: =+A19+1 -> 46335 | B20: =+TEXT(A20,"DDD") -> pon | E20: =+D20-C20 -> 0 | AE20: =SUM(F20:AD20) -> 0
A21: =+A20+1 -> 46336 | B21: =+TEXT(A21,"DDD") -> uto | E21: =+D21-C21 -> 0 | AE21: =SUM(F21:AD21) -> 0
A22: =+A21+1 -> 46337 | B22: =+TEXT(A22,"DDD") -> sri | E22: =+D22-C22 -> 0 | AE22: =SUM(F22:AD22) -> 0
A23: =+A22+1 -> 46338 | B23: =+TEXT(A23,"DDD") -> čet | E23: =+D23-C23 -> 0 | AE23: =SUM(F23:AD23) -> 0
A24: =+A23+1 -> 46339 | B24: =+TEXT(A24,"DDD") -> pet | E24: =+D24-C24 -> 0 | AE24: =SUM(F24:AD24) -> 0
... A41: =+A40+1 -> 46356 | B41: =+TEXT(A41,"DDD") -> pon | E41: =+D41-C41 -> 0 | AE41: =SUM(F41:AD41) -> 0
A44: *** | B44: *** | C44: *** | D44: *** | E44: =SUM(E12:E43) -> 0 | F44: =SUM(F12:F43) -> 0 | G44: =SUM(G12:G43) -> 0 | H44: =SUM(H12:H43) -> 0 | I44: =SUM(I12:I43) -> 0 | J44: =SUM(J12:J43) -> 0 | K44: =SUM(K12:K43) -> 0 | L44: =SUM(L12:L43) -> 0 | ... AD44: =SUM(AD12:AD43) -> 0 | AE44: ***
E45: =+E10 -> Ukupno sati | F45: =+F10 -> 1.smjena | G45: =+G10 -> 2.smjena | H45: =+H10 -> Noćni rad | I45: =+I10 -> Rad Nedjeljom | J45: =+J10 -> Rad praznikom | K45: =+K10 -> Prekovremeni rad | L45: =+L10 -> Vrijeme terenskog rada | ... AE45: =+AE10 -> KONTROLNI ZBROJ
A46: Broj sati nazočnosti na poslu: | G46: =+SUM(F44:M44) -> 0 | J46: Ukupan broj sati : | P46: =+G46+G47 -> 0 | S46: Postotak minulog rada:
A47: Broj sati NEnazočnosti na poslu: | G47: =+SUM(P44:AD44) -> 0

Sheet 12
A1: EVIDENCIJA O RADNOM VREMENU ZAPOSLENIKA
A2: RAD U SMJENAMA ? | E2: =+'01'!E2 -> NE
A3: Raspored 1.smjena | E3: 6 | F3: 14 | G3: Ime i prezime radnika: | M3: =+Podaci!B18 -> MARICA MARINČIĆ | S3: NAZIV TVRTKE I OIB:
A4: Raspored 2.smjena | E4: 14 | F4: 22 | G4: OIB radnika: | M4: =+Podaci!B19 -> 78945612389 | S4: =+Podaci!B4 -> TVRTKA ABC D.O.O.
A5: Noćni rad | E5: 22 | F5: 6 | G5: E-MAIL radnika: | M5: =+Podaci!B31 -> info@metro-servis.hr | S5: =+Podaci!B5 -> 12345678910
A6: MJESEC | D6: =+MONTH(D7) -> 12 | G6: GODINA | J6: =+YEAR(J7) -> 2026 | R6: Broj radnih sati | V6: 7 + 5 | X6: Mogući broj sati u mjesecu
A7: Datum početka | D7: =+A12 -> 46357 | G7: Datum kraja | J7: =+EOMONTH(D7,0) -> 46387 | M7: Broj radnih dana | P7: =+NETWORKDAYS(D7,J7,0) -> 23 | R7: Broj radnih sati | V7: 8 | X7: Mogući broj sati u mjesecu | AC7: =+P7*V7 -> 184
A9: =+YEAR(A12) -> 2026 | F9: Vrijeme / Sati nazočnosti na poslu | N9: Vrijeme / Sati nenazočnosti na poslu zbog
A10: Datum | B10: Dan | C10: Početak rada | D10: Završetak rada | E10: Ukupno sati | F10: 1.smjena | G10: 2.smjena | H10: Noćni rad | I10: Rad Nedjeljom | J10: Rad praznikom | K10: Prekovremeni rad | L10: Vrijeme terenskog rada | M10: Vrijeme pripravnosti | N10: Dnevni odmor | O10: Tjedni odmor | P10: Godišnji odmor | Q10: Neradni dani - blagdani | R10: Privremena nesposobnost za rad - do 42 dana | S10: Privremena nesposobnost za rad - iznad 42 dana | T10: Porodiljni - rodiljni dopust | U10: Plaćeni dopust - odsustnost s rada | V10: Sati očinskog dopusta i dopusta drugog posvojitelja | W10: Neplaćeni dopust - pruž.osobne skrbi | X10: Neplaćen dopust kandidata - razno | Y10: Neplaćeni dopust - na zahtjev radnika | Z10: Krivnje radnika - ne obavlja ugovorene poslove | AA10: Krivnja poslodavca - zastoj | AB10: Vojna obveza ili služenje u ugovornoj pričuvi | AC10: štrajka | AD10: isključenja s rada - lockout | AE10: KONTROLNI ZBROJ
A12: 46357 | B12: =+TEXT(A12,"DDD") -> uto | E12: =+D12-C12 -> 0 | AE12: =SUM(F12:AD12) -> 0
A13: =+A12+1 -> 46358 | B13: =+TEXT(A13,"DDD") -> sri | E13: =+D13-C13 -> 0 | AE13: =SUM(F13:AD13) -> 0
A14: =+A13+1 -> 46359 | B14: =+TEXT(A14,"DDD") -> čet | E14: =+D14-C14 -> 0 | AE14: =SUM(F14:AD14) -> 0
A15: =+A14+1 -> 46360 | B15: =+TEXT(A15,"DDD") -> pet | E15: =+D15-C15 -> 0 | AE15: =SUM(F15:AD15) -> 0
A16: =+A15+1 -> 46361 | B16: =+TEXT(A16,"DDD") -> sub | E16: =+D16-C16 -> 0 | AE16: =SUM(F16:AD16) -> 0
A17: =+A16+1 -> 46362 | B17: =+TEXT(A17,"DDD") -> ned | E17: =+D17-C17 -> 0 | AE17: =SUM(F17:AD17) -> 0
A18: =+A17+1 -> 46363 | B18: =+TEXT(A18,"DDD") -> pon | E18: =+D18-C18 -> 0 | AE18: =SUM(F18:AD18) -> 0
A19: =+A18+1 -> 46364 | B19: =+TEXT(A19,"DDD") -> uto | E19: =+D19-C19 -> 0 | AE19: =SUM(F19:AD19) -> 0
A20: =+A19+1 -> 46365 | B20: =+TEXT(A20,"DDD") -> sri | E20: =+D20-C20 -> 0 | AE20: =SUM(F20:AD20) -> 0
A21: =+A20+1 -> 46366 | B21: =+TEXT(A21,"DDD") -> čet | E21: =+D21-C21 -> 0 | AE21: =SUM(F21:AD21) -> 0
A22: =+A21+1 -> 46367 | B22: =+TEXT(A22,"DDD") -> pet | E22: =+D22-C22 -> 0 | AE22: =SUM(F22:AD22) -> 0
A23: =+A22+1 -> 46368 | B23: =+TEXT(A23,"DDD") -> sub | E23: =+D23-C23 -> 0 | AE23: =SUM(F23:AD23) -> 0
A24: =+A23+1 -> 46369 | B24: =+TEXT(A24,"DDD") -> ned | E24: =+D24-C24 -> 0 | AE24: =SUM(F24:AD24) -> 0
... A42: =+A41+1 -> 46387 | B42: =+TEXT(A42,"DDD") -> čet | E42: =+D42-C42 -> 0 | AE42: =SUM(F42:AD42) -> 0
A44: *** | B44: *** | C44: *** | D44: *** | E44: =SUM(E12:E43) -> 0 | F44: =SUM(F12:F43) -> 0 | G44: =SUM(G12:G43) -> 0 | H44: =SUM(H12:H43) -> 0 | I44: =SUM(I12:I43) -> 0 | J44: =SUM(J12:J43) -> 0 | K44: =SUM(K12:K43) -> 0 | L44: =SUM(L12:L43) -> 0 | ... AD44: =SUM(AD12:AD43) -> 0 | AE44: ***
E45: =+E10 -> Ukupno sati | F45: =+F10 -> 1.smjena | G45: =+G10 -> 2.smjena | H45: =+H10 -> Noćni rad | I45: =+I10 -> Rad Nedjeljom | J45: =+J10 -> Rad praznikom | K45: =+K10 -> Prekovremeni rad | L45: =+L10 -> Vrijeme terenskog rada | ... AE45: =+AE10 -> KONTROLNI ZBROJ
A46: Broj sati nazočnosti na poslu: | G46: =+SUM(F44:M44) -> 0 | J46: Ukupan broj sati : | P46: =+G46+G47 -> 0 | S46: Postotak minulog rada:
A47: Broj sati NEnazočnosti na poslu: | G47: =+SUM(P44:AD44) -> 0
